<?xml version="1.0" ?>
<!-- =================================================================================== -->
<!-- |    This document was autogenerated by xacro from iiwa_striker.urdf.xacro        | -->
<!-- |    EDITING THIS FILE BY HAND IS NOT RECOMMENDED                                 | -->
<!-- =================================================================================== -->
<robot name="virtual_box">
  <material name="DotMaterial">
    <color rgba="0.8 0.0 0.0 0.5"/>
  </material>
  <link name="base">
    <inertial>
      <origin rpy="0 0 0" xyz="0 0 0"/>
      <mass value="0"/>
      <inertia ixx="0" ixy="0" ixz="0" iyy="0" iyz="0" izz="0"/>
    </inertial>
  </link>
  <joint name="base_0" type="prismatic">
    <origin rpy="0 0 0" xyz="0 0 0.0"/>
    <axis xyz="1 1 1"/>
    <parent link="base"/>
    <child link="dot_0"/>
    <limit effort="30" velocity="1.0" lower="0.0" upper="0.1" />
  </joint>
  <link name="dot_0">
    <inertial>
      <origin rpy="0 0 0" xyz="0 0 0"/>
      <mass value="0"/>
      <inertia ixx="0" ixy="0" ixz="0" iyy="0" iyz="0" izz="0"/>
    </inertial>
    <visual>
      <origin rpy="0 0 0" xyz="0 0 0"/>
      <geometry>
        <sphere radius="0.01"/>
      </geometry>
      <material name="DotMaterial"/>
    </visual>
  </link>
  <joint name="base_1" type="prismatic">
    <origin rpy="0 0 0" xyz="0 0 0.0"/>
    <axis xyz="1 1 -1"/>
    <parent link="base"/>
    <child link="dot_1"/>
    <limit effort="30" velocity="1.0" lower="0.0" upper="0.1" />
  </joint>
  <link name="dot_1">
    <inertial>
      <origin rpy="0 0 0" xyz="0 0 0"/>
      <mass value="0"/>
      <inertia ixx="0" ixy="0" ixz="0" iyy="0" iyz="0" izz="0"/>
    </inertial>
    <visual>
      <origin rpy="0 0 0" xyz="0 0 0"/>
      <geometry>
        <sphere radius="0.01"/>
      </geometry>
      <material name="DotMaterial"/>
    </visual>
  </link>
  <joint name="base_2" type="prismatic">
    <origin rpy="0 0 0" xyz="0 0 0.0"/>
    <axis xyz="1 -1 1"/>
    <parent link="base"/>
    <child link="dot_2"/>
    <limit effort="30" velocity="1.0" lower="0.0" upper="0.1" />
  </joint>
  <link name="dot_2">
    <inertial>
      <origin rpy="0 0 0" xyz="0 0 0"/>
      <mass value="0"/>
      <inertia ixx="0" ixy="0" ixz="0" iyy="0" iyz="0" izz="0"/>
    </inertial>
    <visual>
      <origin rpy="0 0 0" xyz="0 0 0"/>
      <geometry>
        <sphere radius="0.01"/>
      </geometry>
      <material name="DotMaterial"/>
    </visual>
  </link>
  <joint name="base_3" type="prismatic">
    <origin rpy="0 0 0" xyz="0 0 0.0"/>
    <axis xyz="1 -1 -1"/>
    <parent link="base"/>
    <child link="dot_3"/>
    <limit effort="30" velocity="1.0" lower="0.0" upper="0.1" />
  </joint>
  <link name="dot_3">
    <inertial>
      <origin rpy="0 0 0" xyz="0 0 0"/>
      <mass value="0"/>
      <inertia ixx="0" ixy="0" ixz="0" iyy="0" iyz="0" izz="0"/>
    </inertial>
    <visual>
      <origin rpy="0 0 0" xyz="0 0 0"/>
      <geometry>
        <sphere radius="0.01"/>
      </geometry>
      <material name="DotMaterial"/>
    </visual>
  </link>
  <joint name="base_4" type="prismatic">
    <origin rpy="0 0 0" xyz="0 0 0.0"/>
    <axis xyz="-1 1 1"/>
    <parent link="base"/>
    <child link="dot_4"/>
    <limit effort="30" velocity="1.0" lower="0.0" upper="0.1" />
  </joint>
  <link name="dot_4">
    <inertial>
      <origin rpy="0 0 0" xyz="0 0 0"/>
      <mass value="0"/>
      <inertia ixx="0" ixy="0" ixz="0" iyy="0" iyz="0" izz="0"/>
    </inertial>
    <visual>
      <origin rpy="0 0 0" xyz="0 0 0"/>
      <geometry>
        <sphere radius="0.01"/>
      </geometry>
      <material name="DotMaterial"/>
    </visual>
  </link>
  <joint name="base_5" type="prismatic">
    <origin rpy="0 0 0" xyz="0 0 0.0"/>
    <axis xyz="-1 1 -1"/>
    <parent link="base"/>
    <child link="dot_5"/>
    <limit effort="30" velocity="1.0" lower="0.0" upper="0.1" />
  </joint>
  <link name="dot_5">
    <inertial>
      <origin rpy="0 0 0" xyz="0 0 0"/>
      <mass value="0"/>
      <inertia ixx="0" ixy="0" ixz="0" iyy="0" iyz="0" izz="0"/>
    </inertial>
    <visual>
      <origin rpy="0 0 0" xyz="0 0 0"/>
      <geometry>
        <sphere radius="0.01"/>
      </geometry>
      <material name="DotMaterial"/>
    </visual>
  </link>
  <joint name="base_6" type="prismatic">
    <origin rpy="0 0 0" xyz="0 0 0.0"/>
    <axis xyz="-1 -1 1"/>
    <parent link="base"/>
    <child link="dot_6"/>
    <limit effort="30" velocity="1.0" lower="0.0" upper="0.1" />
  </joint>
  <link name="dot_6">
    <inertial>
      <origin rpy="0 0 0" xyz="0 0 0"/>
      <mass value="0"/>
      <inertia ixx="0" ixy="0" ixz="0" iyy="0" iyz="0" izz="0"/>
    </inertial>
    <visual>
      <origin rpy="0 0 0" xyz="0 0 0"/>
      <geometry>
        <sphere radius="0.01"/>
      </geometry>
      <material name="DotMaterial"/>
    </visual>
  </link>
  <joint name="base_7" type="prismatic">
    <origin rpy="0 0 0" xyz="0 0 0.0"/>
    <axis xyz="-1 -1 -1"/>
    <parent link="base"/>
    <child link="dot_7"/>
    <limit effort="30" velocity="1.0" lower="0.0" upper="0.1" />
  </joint>
  <link name="dot_7">
    <inertial>
      <origin rpy="0 0 0" xyz="0 0 0"/>
      <mass value="0"/>
      <inertia ixx="0" ixy="0" ixz="0" iyy="0" iyz="0" izz="0"/>
    </inertial>
    <visual>
      <origin rpy="0 0 0" xyz="0 0 0"/>
      <geometry>
        <sphere radius="0.01"/>
      </geometry>
      <material name="DotMaterial"/>
    </visual>
  </link>
</robot>

